<?xml version="1.0" ?>
<!-- =================================================================================== -->
<!-- |    This document was autogenerated by xacro from /home/dan1620/ws_moveit/src/robotics_arm_collection_for_ros/drawing_robot_description/urdf/drawing_robot_description.urdf.xacro | -->
<!-- |    EDITING THIS FILE BY HAND IS NOT RECOMMENDED                                 | -->
<!-- =================================================================================== -->
<robot name="drawing_robot_description">
    <material name="grey_pla">
        <color rgba="0.552 0.501 0.501 1" />
    </material>
    <material name="blue_pla">
        <color rgba="0.035 0.517 0.937 1" />
    </material>
    <gazebo reference="base_link">
        <material>Gazebo/Grey</material>
        <selfCollide>true</selfCollide>
        <plugin name="gazebo_ros_control">
            <robotNamespace>/</robotNamespace>
        </plugin>
    </gazebo>
    <gazebo reference="arm_1">
        <material>Gazebo/Grey</material>
        <selfCollide>true</selfCollide>
    </gazebo>
    <gazebo reference="arm_2">
        <material>Gazebo/Grey</material>
        <selfCollide>true</selfCollide>
    </gazebo>
    <gazebo reference="hand">
        <material>Gazebo/SkyBlue</material>
        <selfCollide>true</selfCollide>
    </gazebo>
    <transmission name="arm1_trans">
        <type>transmission_interface/SimpleTransmission</type>
        <joint name="base_to_arm1">
            <hardwareInterface>hardware_interface/PositionJointInterface</hardwareInterface>
        </joint>
        <actuator name="arm1_motor">
            <hardwareInterface>hardware_interface/PositionJointInterface</hardwareInterface>
            <mechanicalReduction>1</mechanicalReduction>
        </actuator>
    </transmission>
    <transmission name="arm2_trans">
        <type>transmission_interface/SimpleTransmission</type>
        <joint name="arm_2_to_arm_1">
            <hardwareInterface>hardware_interface/PositionJointInterface</hardwareInterface>
        </joint>
        <actuator name="arm2_motor">
            <hardwareInterface>hardware_interface/PositionJointInterface</hardwareInterface>
            <mechanicalReduction>1</mechanicalReduction>
        </actuator>
    </transmission>
    <transmission name="hand_trans">
        <type>transmission_interface/SimpleTransmission</type>
        <joint name="hand_to_arm2">
            <hardwareInterface>hardware_interface/EffortJointInterface</hardwareInterface>
        </joint>
        <actuator name="hand_motor">
            <hardwareInterface>hardware_interface/EffortJointInterface</hardwareInterface>
            <mechanicalReduction>1</mechanicalReduction>
        </actuator>
    </transmission>
    <gazebo>
        <plugin filename="libgazebo_ros_control.so" name="control">
            <robotNamespace>/</robotNamespace>
        </plugin>
    </gazebo>
    <!-- ____________________________________ BASE LINK DEFINITIONS ______________________________________________-->
    <link name="world" />
    <joint name="base_joint" type="fixed">
        <parent link="world" />
        <child link="base_link" />
        <origin xyz="0.0 0.0 0.0175" />
    </joint>
    <link name="base_link">
        <inertial>
            <origin rpy="0 0 0" xyz="2.2369E-05 -0.0095991 0.018203" />
            <mass value="0.19207" />
            <inertia ixx="0.00010604" ixy="-5.7604E-12" ixz="2.8656E-10" iyy="9.0218E-05" iyz="-8.2785E-06" izz="0.0001446" />
        </inertial>
        <visual>
            <origin rpy="0 0 0" xyz="0 0 0" />
            <geometry>
                <mesh filename="package://drawing_robot_description/meshes/base_link.STL" />
            </geometry>
            <material name="grey_pla" />
        </visual>
        <collision>
            <origin rpy="0 0 0" xyz="0 0 0" />
            <geometry>
                <mesh filename="package://drawing_robot_description/meshes/base_link.STL" />
            </geometry>
        </collision>
    </link>
    <!-- ________________________________________ ARM 1 DEFINITIONS ______________________________________________-->
    <link name="arm_1">
        <inertial>
            <origin rpy="0 0 0" xyz="9.8801E-05 0.081425 0.0056756" />
            <mass value="0.16147" />
            <inertia ixx="0.00012764" ixy="-5.7417E-12" ixz="2.8659E-10" iyy="5.7319E-05" iyz="6.0193E-06" izz="9.0777E-05" />
        </inertial>
        <visual>
            <origin rpy="0 0 0" xyz="0 0 0" />
            <geometry>
                <mesh filename="package://drawing_robot_description/meshes/arm_1.STL" />
            </geometry>
            <material name="grey_pla" />
        </visual>
        <collision>
            <origin rpy="0 0 0" xyz="0 0 0" />
            <geometry>
                <mesh filename="package://drawing_robot_description/meshes/arm_1.STL" />
            </geometry>
        </collision>
    </link>
    <joint name="base_to_arm1" type="revolute">
        <origin rpy="0 0 0" xyz="0 0.019815 0.0295" />
        <parent link="base_link" />
        <child link="arm_1" />
        <axis xyz="0 0 1" />
        <limit effort="7.605" lower="-1.5707" upper="1.5707" velocity="8.05" />
    </joint>
    <!-- ________________________________________ ARM 2 DEFINITIONS ______________________________________________-->
    <link name="arm_2">
        <inertial>
            <origin rpy="0 0 0" xyz="-0.0040009 0.073708 0.014062" />
            <mass value="0.15444" />
            <inertia ixx="7.5619E-05" ixy="-8.4032E-08" ixz="1.738E-06" iyy="6.6114E-05" iyz="-3.3092E-06" izz="4.0148E-05" />
        </inertial>
        <visual>
            <origin rpy="0 0 0" xyz="0 0 0" />
            <geometry>
                <mesh filename="package://drawing_robot_description/meshes/arm_2.STL" />
            </geometry>
            <material name="grey_pla" />
        </visual>
        <collision>
            <origin rpy="0 0 0" xyz="0 0 0" />
            <geometry>
                <mesh filename="package://drawing_robot_description/meshes/arm_2.STL" />
            </geometry>
        </collision>
    </link>
    <joint name="arm_2_to_arm_1" type="revolute">
        <origin rpy="0 0 0" xyz="0 0.12845 0.00093551" />
        <parent link="arm_1" />
        <child link="arm_2" />
        <axis xyz="0 0 1" />
        <limit effort="7.605" lower="-1.5707" upper="1.5707" velocity="8.05" />
    </joint>
    <!-- ________________________________________ END EFFECTOR DEFINITIONS ______________________________________________-->
    <link name="hand">
        <inertial>
            <origin rpy="0 0 0" xyz="-0.00030849 -0.0071882 0.0050741" />
            <mass value="0.078332" />
            <inertia ixx="9.0141E-05" ixy="-1.4456E-07" ixz="-1.3295E-07" iyy="9.0236E-05" iyz="3.1377E-07" izz="9.782E-06" />
        </inertial>
        <visual>
            <origin rpy="0 0 0" xyz="0 0 0" />
            <geometry>
                <mesh filename="package://drawing_robot_description/meshes/hand.STL" />
            </geometry>
            <material name="blue_pla" />
        </visual>
        <collision>
            <origin rpy="0 0 0" xyz="0 0 0" />
            <geometry>
                <mesh filename="package://drawing_robot_description/meshes/hand.STL" />
            </geometry>
        </collision>
    </link>
    <joint name="hand_to_arm2" type="prismatic">
        <origin rpy="3.1416 0 0" xyz="0 0.11785 0.027766" />
        <parent link="arm_2" />
        <child link="hand" />
        <axis xyz="0 0 -1" />
        <limit effort="0.636" lower="-0.02" upper="0" velocity="3" />
    </joint>
</robot>

